Workbook
Name ВстроеннаяВременнаяШкала_Дата_постановления: #N/A
Name Срез_Статья_КоАП1: #N/A
Name Срез_Тип_лица1: #N/A
Name Срез_Штраф_факт1: #N/A
Name Срез_Штраф_факт2: #N/A

Sheet компании+описание
A1: Номер случая | B1: Дата | C1: Субъект | D1: Описание
A2: 1 | B2: 17.02.2026 | C2: Акционерное общество «Негосударственный пенсионный фонд «Ростех» | D2: По результатам рассмотрения материалов дела об административном правонарушении № ЦА-38-ЮЛ-26-258, возбуждённого за совершение административного правонарушения, ответственность за которое предусмотрена частью 9 статьи 15.29 Кодекса Российской Федерации об административных правонарушениях, АО «НПФ «Ростех» назначено административное наказание в виде штрафа в размере 700 000 рублей. Постановление вступило в законную силу 17.02.2026.
A3: 2 | B3: 17.02.2026 | C3: Общество с ограниченной ответственностью «Управляющая компания_x000D_ «Атон-менеджмент» | D3: По результатам рассмотрения материалов дела об административном правонарушении № ЦА-38-ЮЛ-26-92, возбужденного за совершение административного правонарушения, ответственность за которое предусмотрена частью 6 статьи 15.29 КоАП РФ, Обществу с ограниченной ответственностью «Управляющая компания «Атон-менеджмент» назначено административное наказание в виде штрафа в размере 700 000 рублей. Постановление вступило в законную силу 17.02.2026.По результатам рассмотрения материалов дела об административном правонарушении № ЦА-38-ЮЛ-26-93, возбужденного за совершение административного правонарушения, ответственность за которое предусмотрена частью 12 статьи 15.29 КоАП РФ, Обществу с ограниченной ответственностью «Управляющая компания «Атон-менеджмент» назначено административное наказание в виде штрафа в размере 320 000 рублей. Постановление вступило в законную силу 17.02.2026.
A4: 3 | B4: 13.02.2026 | C4: Акционерное общество_x000D_ Управляющая компания «Центр Эссет Менеджмент» | D4: По результатам рассмотрения материалов дела об административном правонарушении № ЦА-38-ЮЛ-26-12, возбужденного за совершение административного правонарушения, ответственность за которое предусмотрена частью 12 статьи 15.29 КоАП РФ, Акционерному обществу Управляющей компании «Центр Эссет Менеджмент» назначено административное наказание в виде предупреждения. Постановление вступило в законную силу 13.02.2026.
A5: 4 | B5: 10.02.2026 | C5: АО «ИК «РИКОМ-ТРАСТ» | D5: По результатам рассмотрения материалов дела об административном правонарушении № ЦА-34-ЮЛ-26-294, возбужденного за совершение административного правонарушения, ответственность за которое предусмотрена частью 9 статьи 15.29 КоАП РФ, акционерному обществу «Инвестиционная компания «РИКОМ-ТРАСТ» назначено административное наказание в виде штрафа размером 1 000 000 (один миллион) рублей. Постановление от 26.01.2026 № 26-294/3110-1 о назначении административного наказания вступило в законную силу 10.02.2026.
A6: 5 | B6: 10.02.2026 | C6: Акционерное общество ВИМ Инвестиции | D6: По результатам рассмотрения материалов дела об административном правонарушении № ЦА-38-ЮЛ-26-19, возбуждённого за совершение административного правонарушения, ответственность за которое предусмотрена частью 12 статьи 15.29 Кодекса Российской Федерации об административных правонарушениях, АО ВИМ Инвестиции назначено административное наказание в виде штрафа в размере 350 000 рублей. Постановление вступило в законную силу 10.02.2026.
A7: 6 | B7: 10.02.2026 | C7: Общество с ограниченной_x000D_ ответственностью_x000D_ «Управляющая компания_x000D_ «Ресурс» | D7: По результатам рассмотрения материалов дела об административном правонарушении № ЦА-38-ЮЛ-26-2, возбужденного за совершение административного правонарушения, ответственность за которое предусмотрена частью 6 статьи 15.29 КоАП РФ, Обществу с ограниченной ответственностью «Управляющая компания «Ресурс» назначено административное наказание в виде предупреждения. Постановление вступило в законную силу 10.02.2026.
A8: 7 | B8: 10.02.2026 | C8: Общество с ограниченной ответственностью «ТрастЮнион Эссет Менеджмент» | D8: По результатам рассмотрения материалов дела об административном правонарушении № ЦА-38-ЮЛ-26-85, возбужденного за совершение административного правонарушения, ответственность за которое предусмотрена частью 12 статьи 15.29 КоАП РФ, Обществу с ограниченной ответственностью «ТрастЮнион Эссет Менеджмент» назначено административное наказание в виде предупреждения. Постановление вступило в законную силу 10.02.2026.
A9: 8 | B9: 10.02.2026 | C9: Акционерное общество «Управляющая Компания ТРИНФИКО» | D9: По результатам рассмотрения материалов дела об административном правонарушении № ЦА-38-ЮЛ-26-6, возбужденного за совершение административного правонарушения, ответственность за которое предусмотрена частью 5 статьи 15.29 КоАП РФ, Акционерному обществу «Управляющая Компания ТРИНФИКО» назначено административное наказание в виде штрафа в размере 250 000 рублей. Постановление вступило в законную силу 10.02.2026.
A10: 9 | B10: 09.02.2026 | C10: ООО «Цифра брокер» | D10: По результатам рассмотрения материалов дела об административном правонарушении № ЦА-34-ЮЛ-26-191, возбужденного за совершение административного правонарушения, ответственность за которое предусмотрена частью 12 статьи 15.29 КоАП РФ, ООО «Цифра брокер» назначено административное наказание в виде штрафа в размере 300 000 рублей. Постановление № 26-191/3110-1 о назначении административного наказания вступило в законную силу 07.02.2026.
A11: 10 | B11: 06.02.2026 | C11: Голубков Виктор Владимирович | D11: По результатам рассмотрения материалов дела об административном правонарушении № ЦА-34-Гр-25-21433, возбужденного за совершение административного правонарушения, ответственность за которое предусмотрена статьей 15.30 Кодекса Российской Федерации об административных правонарушениях, Голубкову Виктору Владимировичу назначено административное наказание в виде штрафа в размере 3 000 рублей. Постановление от 18.12.2025 № 25-21433/3110-1 о назначении административного наказания вступило в законную силу 03.02.2026.
A12: 11 | B12: 06.02.2026 | C12: генеральный директор общества с ограниченной ответственностью «Тринити Шиппинг» Ярошенко Александр Иванович | D12: По результатам рассмотрения материалов дела об административном правонарушении № ЦА-34-ДЛ-25-20686, возбужденного за совершение административного правонарушения, ответственность за которое предусмотрена статьей 15.30 Кодекса Российской Федерации об административных правонарушениях, генеральному директору общества с ограниченной ответственностью «Тринити Шиппинг» Ярошенко Александру Ивановичу назначено административное наказание в виде штрафа в размере 30 000 рублей. Постановление от 25.12.2025 № 25-20686/3110-1 о назначении административного наказания вступило в законную силу 31.01.2026.
A13: 12 | B13: 06.02.2026 | C13: Гальямова Наталья Александровна | D13: По результатам рассмотрения материалов дела об административном правонарушении № ЦА-34-ГР-25-21130, возбужденного за совершение административного правонарушения, ответственность за которое предусмотрена статьей 15.30 Кодекса Российской Федерации об административных правонарушениях, Гальямовой Наталье Александровне назначено административное наказание в виде штрафа в размере 3 000 рублей. Постановление от 25.12.2025 № 25-21130/3110-1 о назначении административного наказания вступило в законную силу 06.02.2026.
... A438: 437 | B438: 09.01.2025 | C438: Акционерное общество «Управляющая компания «Первая» | D438: По результатам рассмотрения материалов дела об административном правонарушении № ЦА-38-ЮЛ-24-14076 возбужденного за совершение административного правонарушения, ответственность за которое предусмотрена частью 12 статьи 15.29 КоАП РФ, АО УК «Первая» назначено административное наказание в виде штрафа в размере 300 000 рублей. Постановление вступило в законную силу 29.12.2024.

Sheet готовая таблица
A1: Номер случая | B1: Дата постановления | C1: Субъект | D1: Тип лица | E1: Статья КоАП | F1: Штраф факт | G1: мин | H1: макс | I1: Превышышение над мин размером %/min | J1: Описание статьи
A2: 1 | B2: 17.02.2026 | C2: Акционерное общество «Негосударственный пенсионный фонд «Ростех» | D2: Юридическое лицо | E2: ч.9 ст.15.29 КоАП РФ | F2: 700000 | G2: 700000 | H2: 1000000 | I2: {=_xlfn.IFS(F2=H2,1,F2=G2,0,F2<>G2,(F2-G2)/(G2))} -> 0 | J2: =VLOOKUP($E2,статьи!$G$2:$I$24,2,) -> Воспрепятствование профессиональным участником рынка ценных бумаг, клиринговой организацией, лицом, осуществляющим функции центрального контрагента, акционерным инвестиционным фондом, негосударственным пенсионным фондом, управляющей компанией акционерного инвестиционного фонда, паевого инвестиционного фонда или негосударственного пенсионного фонда либо специализированным депозитарием акционерного инвестиционного фонда, паевого инвестиционного фонда или негосударственного пенсионного фонда проведению Банком России проверок либо неисполнение или ненадлежащее исполнение предписаний Банка России
A3: 2 | B3: 17.02.2026 | C3: Общество с ограниченной ответственностью «Управляющая компания_x000D_ «Атон-менеджмент» | D3: Юридическое лицо | E3: ч.6 ст.15.29 КоАП РФ | F3: 700000 | G3: 700000 | H3: 1000000 | I3: {=_xlfn.IFS(F3=H3,1,F3=G3,0,F3<>G3,(F3-G3)/(G3))} -> 0 | J3: =VLOOKUP($E3,статьи!$G$2:$I$24,2,) -> Нарушение управляющей компанией акционерного инвестиционного фонда или паевого инвестиционного фонда предусмотренных федеральными законами и иными нормативными правовыми актами Российской Федерации ограничений ее деятельности -
A4: 2 | B4: 17.02.2026 | C4: Общество с ограниченной ответственностью «Управляющая компания_x000D_ «Атон-менеджмент» | D4: Юридическое лицо | E4: ч.12 ст.15.29 КоАП РФ | F4: 320000 | G4: 300000 | H4: 500000 | I4: {=_xlfn.IFS(F4=H4,1,F4=G4,0,F4<>G4,(F4-G4)/(G4))} -> 0.066666667 | J4: =VLOOKUP($E4,статьи!$G$2:$I$24,2,) -> Иное нарушение профессиональным участником рынка ценных бумаг, репозитарием, клиринговой организацией, лицом, осуществляющим функции центрального контрагента, акционерным инвестиционным фондом, негосударственным пенсионным фондом, управляющей компанией акционерного инвестиционного фонда, паевого инвестиционного фонда или негосударственного пенсионного фонда либо специализированным депозитарием акционерного инвестиционного фонда, паевого инвестиционного фонда или негосударственного пенсионного фонда при осуществлении ими соответствующих видов деятельности установленных законодательством требований к этим видам деятельности, за исключением случаев, предусмотренных частями 1 - 11 настоящей статьи, статьями 13.25, 15.18 - 15.20, 15.22, 15.23.1, 15.24.1, 15.30 и 19.7.3 настоящего Кодекса
A5: 3 | B5: 13.02.2026 | C5: Акционерное общество_x000D_ Управляющая компания «Центр Эссет Менеджмент» | D5: Юридическое лицо | E5: ч.12 ст.15.29 КоАП РФ | F5: предупреждение | G5: 300000 | H5: 500000 | I5: {=_xlfn.IFS(F5=H5,1,F5=G5,0,F5<>G5,(F5-G5)/(G5))} -> #VALUE! | J5: =VLOOKUP($E5,статьи!$G$2:$I$24,2,) -> Иное нарушение профессиональным участником рынка ценных бумаг, репозитарием, клиринговой организацией, лицом, осуществляющим функции центрального контрагента, акционерным инвестиционным фондом, негосударственным пенсионным фондом, управляющей компанией акционерного инвестиционного фонда, паевого инвестиционного фонда или негосударственного пенсионного фонда либо специализированным депозитарием акционерного инвестиционного фонда, паевого инвестиционного фонда или негосударственного пенсионного фонда при осуществлении ими соответствующих видов деятельности установленных законодательством требований к этим видам деятельности, за исключением случаев, предусмотренных частями 1 - 11 настоящей статьи, статьями 13.25, 15.18 - 15.20, 15.22, 15.23.1, 15.24.1, 15.30 и 19.7.3 настоящего Кодекса
A6: 4 | B6: 10.02.2026 | C6: АО «ИК «РИКОМ-ТРАСТ» | D6: Юридическое лицо | E6: ч.9 ст.15.29 КоАП РФ | F6: 1000000 | G6: 700000 | H6: 1000000 | I6: {=_xlfn.IFS(F6=H6,1,F6=G6,0,F6<>G6,(F6-G6)/(G6))} -> 1 | J6: =VLOOKUP($E6,статьи!$G$2:$I$24,2,) -> Воспрепятствование профессиональным участником рынка ценных бумаг, клиринговой организацией, лицом, осуществляющим функции центрального контрагента, акционерным инвестиционным фондом, негосударственным пенсионным фондом, управляющей компанией акционерного инвестиционного фонда, паевого инвестиционного фонда или негосударственного пенсионного фонда либо специализированным депозитарием акционерного инвестиционного фонда, паевого инвестиционного фонда или негосударственного пенсионного фонда проведению Банком России проверок либо неисполнение или ненадлежащее исполнение предписаний Банка России
A7: 5 | B7: 10.02.2026 | C7: Акционерное общество ВИМ Инвестиции | D7: Юридическое лицо | E7: ч.12 ст.15.29 КоАП РФ | F7: 350000 | G7: 300000 | H7: 500000 | I7: {=_xlfn.IFS(F7=H7,1,F7=G7,0,F7<>G7,(F7-G7)/(G7))} -> 0.16666667 | J7: =VLOOKUP($E7,статьи!$G$2:$I$24,2,) -> Иное нарушение профессиональным участником рынка ценных бумаг, репозитарием, клиринговой организацией, лицом, осуществляющим функции центрального контрагента, акционерным инвестиционным фондом, негосударственным пенсионным фондом, управляющей компанией акционерного инвестиционного фонда, паевого инвестиционного фонда или негосударственного пенсионного фонда либо специализированным депозитарием акционерного инвестиционного фонда, паевого инвестиционного фонда или негосударственного пенсионного фонда при осуществлении ими соответствующих видов деятельности установленных законодательством требований к этим видам деятельности, за исключением случаев, предусмотренных частями 1 - 11 настоящей статьи, статьями 13.25, 15.18 - 15.20, 15.22, 15.23.1, 15.24.1, 15.30 и 19.7.3 настоящего Кодекса
A8: 6 | B8: 10.02.2026 | C8: Общество с ограниченной_x000D_ ответственностью_x000D_ «Управляющая компания_x000D_ «Ресурс» | D8: Юридическое лицо | E8: ч.6 ст.15.29 КоАП РФ | F8: предупреждение | G8: 700000 | H8: 1000000 | I8: {=_xlfn.IFS(F8=H8,1,F8=G8,0,F8<>G8,(F8-G8)/(G8))} -> #VALUE! | J8: =VLOOKUP($E8,статьи!$G$2:$I$24,2,) -> Нарушение управляющей компанией акционерного инвестиционного фонда или паевого инвестиционного фонда предусмотренных федеральными законами и иными нормативными правовыми актами Российской Федерации ограничений ее деятельности -
A9: 7 | B9: 10.02.2026 | C9: Общество с ограниченной ответственностью «ТрастЮнион Эссет Менеджмент» | D9: Юридическое лицо | E9: ч.12 ст.15.29 КоАП РФ | F9: предупреждение | G9: 300000 | H9: 500000 | I9: {=_xlfn.IFS(F9=H9,1,F9=G9,0,F9<>G9,(F9-G9)/(G9))} -> #VALUE! | J9: =VLOOKUP($E9,статьи!$G$2:$I$24,2,) -> Иное нарушение профессиональным участником рынка ценных бумаг, репозитарием, клиринговой организацией, лицом, осуществляющим функции центрального контрагента, акционерным инвестиционным фондом, негосударственным пенсионным фондом, управляющей компанией акционерного инвестиционного фонда, паевого инвестиционного фонда или негосударственного пенсионного фонда либо специализированным депозитарием акционерного инвестиционного фонда, паевого инвестиционного фонда или негосударственного пенсионного фонда при осуществлении ими соответствующих видов деятельности установленных законодательством требований к этим видам деятельности, за исключением случаев, предусмотренных частями 1 - 11 настоящей статьи, статьями 13.25, 15.18 - 15.20, 15.22, 15.23.1, 15.24.1, 15.30 и 19.7.3 настоящего Кодекса
A10: 8 | B10: 10.02.2026 | C10: Акционерное общество «Управляющая Компания ТРИНФИКО» | D10: Юридическое лицо | E10: ч.5 ст.15.29 КоАП РФ | F10: 250000 | G10: 500000 | H10: 700000 | I10: {=_xlfn.IFS(F10=H10,1,F10=G10,0,F10<>G10,(F10-G10)/(G10))} -> -0.5 | J10: =VLOOKUP($E10,статьи!$G$2:$I$24,2,) -> Нарушение установленных нормативными правовыми актами Российской Федерации и инвестиционной декларацией акционерного инвестиционного фонда или паевого инвестиционного фонда требований к составу активов акционерных инвестиционных фондов или паевых инвестиционных фондов либо неустранение нарушений в структуре активов акционерных инвестиционных фондов или паевых инвестиционных фондов -
A11: 9 | B11: 09.02.2026 | C11: ООО «Цифра брокер» | D11: Юридическое лицо | E11: ч.12 ст.15.29 КоАП РФ | F11: 300000 | G11: 300000 | H11: 500000 | I11: {=_xlfn.IFS(F11=H11,1,F11=G11,0,F11<>G11,(F11-G11)/(G11))} -> 0 | J11: =VLOOKUP($E11,статьи!$G$2:$I$24,2,) -> Иное нарушение профессиональным участником рынка ценных бумаг, репозитарием, клиринговой организацией, лицом, осуществляющим функции центрального контрагента, акционерным инвестиционным фондом, негосударственным пенсионным фондом, управляющей компанией акционерного инвестиционного фонда, паевого инвестиционного фонда или негосударственного пенсионного фонда либо специализированным депозитарием акционерного инвестиционного фонда, паевого инвестиционного фонда или негосударственного пенсионного фонда при осуществлении ими соответствующих видов деятельности установленных законодательством требований к этим видам деятельности, за исключением случаев, предусмотренных частями 1 - 11 настоящей статьи, статьями 13.25, 15.18 - 15.20, 15.22, 15.23.1, 15.24.1, 15.30 и 19.7.3 настоящего Кодекса
A12: 10 | B12: 06.02.2026 | C12: Голубков Виктор Владимирович | D12: Гражданин | E12: ст.15.30 КоАП РФ | F12: 3000 | G12: 3000 | H12: 5000 | I12: {=_xlfn.IFS(F12=H12,1,F12=G12,0,F12<>G12,(F12-G12)/(G12))} -> 0 | J12: =VLOOKUP($E12,статьи!$G$2:$I$24,2,) -> Манипулирование рынком, если это действие не содержит уголовно наказуемого деяния
A13: 11 | B13: 06.02.2026 | C13: генеральный директор общества с ограниченной ответственностью «Тринити Шиппинг» Ярошенко Александр Иванович | D13: Должностное лицо | E13: ст.15.30 КоАП РФ | F13: 30000 | G13: 30000 | H13: 50000 | I13: {=_xlfn.IFS(F13=H13,1,F13=G13,0,F13<>G13,(F13-G13)/(G13))} -> 0 | J13: =VLOOKUP($E13,статьи!$G$2:$I$24,2,) -> Манипулирование рынком, если это действие не содержит уголовно наказуемого деяния
A14: 12 | B14: 06.02.2026 | C14: Гальямова Наталья Александровна | D14: Гражданин | E14: ст.15.30 КоАП РФ | F14: 3000 | G14: 3000 | H14: 5000 | I14: {=_xlfn.IFS(F14=H14,1,F14=G14,0,F14<>G14,(F14-G14)/(G14))} -> 0 | J14: =VLOOKUP($E14,статьи!$G$2:$I$24,2,) -> Манипулирование рынком, если это действие не содержит уголовно наказуемого деяния
A15: 13 | B15: 03.02.2026 | C15: Чмыхало Юлия Анатольевна | D15: Гражданин | E15: ст.15.30 КоАП РФ | F15: 3000 | G15: 3000 | H15: 5000 | I15: {=_xlfn.IFS(F15=H15,1,F15=G15,0,F15<>G15,(F15-G15)/(G15))} -> 0 | J15: =VLOOKUP($E15,статьи!$G$2:$I$24,2,) -> Манипулирование рынком, если это действие не содержит уголовно наказуемого деяния
A16: 14 | B16: 30.01.2026 | C16: Усольцева Яна Германовна | D16: Гражданин | E16: ст.15.30 КоАП РФ | F16: 3000 | G16: 3000 | H16: 5000 | I16: {=_xlfn.IFS(F16=H16,1,F16=G16,0,F16<>G16,(F16-G16)/(G16))} -> 0 | J16: =VLOOKUP($E16,статьи!$G$2:$I$24,2,) -> Манипулирование рынком, если это действие не содержит уголовно наказуемого деяния
A17: 15 | B17: 30.01.2026 | C17: Краснова Галина Ивановна | D17: Гражданин | E17: ст.15.30 КоАП РФ | F17: 3000 | G17: 3000 | H17: 5000 | I17: {=_xlfn.IFS(F17=H17,1,F17=G17,0,F17<>G17,(F17-G17)/(G17))} -> 0 | J17: =VLOOKUP($E17,статьи!$G$2:$I$24,2,) -> Манипулирование рынком, если это действие не содержит уголовно наказуемого деяния
A18: 16 | B18: 30.01.2026 | C18: Артамонов Валерий Геннадьевич | D18: Гражданин | E18: ст.15.30 КоАП РФ | F18: 3000 | G18: 3000 | H18: 5000 | I18: {=_xlfn.IFS(F18=H18,1,F18=G18,0,F18<>G18,(F18-G18)/(G18))} -> 0 | J18: =VLOOKUP($E18,статьи!$G$2:$I$24,2,) -> Манипулирование рынком, если это действие не содержит уголовно наказуемого деяния
A19: 17 | B19: 30.01.2026 | C19: Манюкова Татьяна Васильевна | D19: Гражданин | E19: ст.15.30 КоАП РФ | F19: 3000 | G19: 3000 | H19: 5000 | I19: {=_xlfn.IFS(F19=H19,1,F19=G19,0,F19<>G19,(F19-G19)/(G19))} -> 0 | J19: =VLOOKUP($E19,статьи!$G$2:$I$24,2,) -> Манипулирование рынком, если это действие не содержит уголовно наказуемого деяния
A20: 18 | B20: 30.01.2026 | C20: Доценко Марина Сергеевна | D20: Гражданин | E20: ст.15.30 КоАП РФ | F20: 3000 | G20: 3000 | H20: 5000 | I20: {=_xlfn.IFS(F20=H20,1,F20=G20,0,F20<>G20,(F20-G20)/(G20))} -> 0 | J20: =VLOOKUP($E20,статьи!$G$2:$I$24,2,) -> Манипулирование рынком, если это действие не содержит уголовно наказуемого деяния
A21: 19 | B21: 30.01.2026 | C21: Гальямов Марсель Геральдович | D21: Гражданин | E21: ст.15.30 КоАП РФ | F21: 3000 | G21: 3000 | H21: 5000 | I21: {=_xlfn.IFS(F21=H21,1,F21=G21,0,F21<>G21,(F21-G21)/(G21))} -> 0 | J21: =VLOOKUP($E21,статьи!$G$2:$I$24,2,) -> Манипулирование рынком, если это действие не содержит уголовно наказуемого деяния
A22: 20 | B22: 30.01.2026 | C22: Садыров Игорь Рашидович | D22: Гражданин | E22: ст.15.30 КоАП РФ | F22: 3000 | G22: 3000 | H22: 5000 | I22: {=_xlfn.IFS(F22=H22,1,F22=G22,0,F22<>G22,(F22-G22)/(G22))} -> 0 | J22: =VLOOKUP($E22,статьи!$G$2:$I$24,2,) -> Манипулирование рынком, если это действие не содержит уголовно наказуемого деяния
A23: 21 | B23: 27.01.2026 | C23: Карчевский Павел Владимирович | D23: Гражданин | E23: ст.15.30 КоАП РФ | F23: 3000 | G23: 3000 | H23: 5000 | I23: {=_xlfn.IFS(F23=H23,1,F23=G23,0,F23<>G23,(F23-G23)/(G23))} -> 0 | J23: =VLOOKUP($E23,статьи!$G$2:$I$24,2,) -> Манипулирование рынком, если это действие не содержит уголовно наказуемого деяния
A24: 22 | B24: 27.01.2026 | C24: Шушин Олег Игоревич | D24: Гражданин | E24: ст.15.30 КоАП РФ | F24: 3000 | G24: 3000 | H24: 5000 | I24: {=_xlfn.IFS(F24=H24,1,F24=G24,0,F24<>G24,(F24-G24)/(G24))} -> 0 | J24: =VLOOKUP($E24,статьи!$G$2:$I$24,2,) -> Манипулирование рынком, если это действие не содержит уголовно наказуемого деяния
A25: 23 | B25: 26.01.2026 | C25: Беломытцева Наталия Сергеевна | D25: Гражданин | E25: ст.15.30 КоАП РФ | F25: 3000 | G25: 3000 | H25: 5000 | I25: {=_xlfn.IFS(F25=H25,1,F25=G25,0,F25<>G25,(F25-G25)/(G25))} -> 0 | J25: =VLOOKUP($E25,статьи!$G$2:$I$24,2,) -> Манипулирование рынком, если это действие не содержит уголовно наказуемого деяния
A26: 24 | B26: 23.01.2026 | C26: Ретровская Нина Борисовна | D26: Гражданин | E26: ст.15.30 КоАП РФ | F26: 3000 | G26: 3000 | H26: 5000 | I26: {=_xlfn.IFS(F26=H26,1,F26=G26,0,F26<>G26,(F26-G26)/(G26))} -> 0 | J26: =VLOOKUP($E26,статьи!$G$2:$I$24,2,) -> Манипулирование рынком, если это действие не содержит уголовно наказуемого деяния
A27: 25 | B27: 23.01.2026 | C27: Исаченко Наталия Николаевна | D27: Гражданин | E27: ст.15.30 КоАП РФ | F27: 3000 | G27: 3000 | H27: 5000 | I27: {=_xlfn.IFS(F27=H27,1,F27=G27,0,F27<>G27,(F27-G27)/(G27))} -> 0 | J27: =VLOOKUP($E27,статьи!$G$2:$I$24,2,) -> Манипулирование рынком, если это действие не содержит уголовно наказуемого деяния
A28: 26 | B28: 23.01.2026 | C28: Беломытцев Павел Анатольевич | D28: Гражданин | E28: ст.15.30 КоАП РФ | F28: 3000 | G28: 3000 | H28: 5000 | I28: {=_xlfn.IFS(F28=H28,1,F28=G28,0,F28<>G28,(F28-G28)/(G28))} -> 0 | J28: =VLOOKUP($E28,статьи!$G$2:$I$24,2,) -> Манипулирование рынком, если это действие не содержит уголовно наказуемого деяния
A29: 27 | B29: 23.01.2026 | C29: Зайцев Александр Олегович | D29: Гражданин | E29: ст.15.30 КоАП РФ | F29: 3000 | G29: 3000 | H29: 5000 | I29: {=_xlfn.IFS(F29=H29,1,F29=G29,0,F29<>G29,(F29-G29)/(G29))} -> 0 | J29: =VLOOKUP($E29,статьи!$G$2:$I$24,2,) -> Манипулирование рынком, если это действие не содержит уголовно наказуемого деяния
A30: 28 | B30: 23.01.2026 | C30: Нарушева Елена Гаптелахатовна | D30: Гражданин | E30: ст.15.30 КоАП РФ | F30: 3000 | G30: 3000 | H30: 5000 | I30: {=_xlfn.IFS(F30=H30,1,F30=G30,0,F30<>G30,(F30-G30)/(G30))} -> 0 | J30: =VLOOKUP($E30,статьи!$G$2:$I$24,2,) -> Манипулирование рынком, если это действие не содержит уголовно наказуемого деяния
A31: 29 | B31: 23.01.2026 | C31: Нарушев Андрей Иванович | D31: Гражданин | E31: ст.15.30 КоАП РФ | F31: 3000 | G31: 3000 | H31: 5000 | I31: {=_xlfn.IFS(F31=H31,1,F31=G31,0,F31<>G31,(F31-G31)/(G31))} -> 0 | J31: =VLOOKUP($E31,статьи!$G$2:$I$24,2,) -> Манипулирование рынком, если это действие не содержит уголовно наказуемого деяния
A32: 30 | B32: 19.01.2026 | C32: ИП Панов Александр Константинович | D32: Гражданин | E32: ст.15.30 КоАП РФ | F32: 30000 | G32: 3000 | H32: 5000 | I32: {=_xlfn.IFS(F32=H32,1,F32=G32,0,F32<>G32,(F32-G32)/(G32))} -> 9 | J32: =VLOOKUP($E32,статьи!$G$2:$I$24,2,) -> Манипулирование рынком, если это действие не содержит уголовно наказуемого деяния
A33: 31 | B33: 19.01.2026 | C33: ИП Панов Владимир Константинович | D33: Гражданин | E33: ст.15.30 КоАП РФ | F33: 30000 | G33: 3000 | H33: 5000 | I33: {=_xlfn.IFS(F33=H33,1,F33=G33,0,F33<>G33,(F33-G33)/(G33))} -> 9 | J33: =VLOOKUP($E33,статьи!$G$2:$I$24,2,) -> Манипулирование рынком, если это действие не содержит уголовно наказуемого деяния
A34: 32 | B34: 19.01.2026 | C34: Оганезян Роман Рафикович | D34: Гражданин | E34: ст.15.30 КоАП РФ | F34: 3000 | G34: 3000 | H34: 5000 | I34: {=_xlfn.IFS(F34=H34,1,F34=G34,0,F34<>G34,(F34-G34)/(G34))} -> 0 | J34: =VLOOKUP($E34,статьи!$G$2:$I$24,2,) -> Манипулирование рынком, если это действие не содержит уголовно наказуемого деяния
A35: 33 | B35: 19.01.2026 | C35: Клименко Артем Валерьевич | D35: Гражданин | E35: ст.15.30 КоАП РФ | F35: 3000 | G35: 3000 | H35: 5000 | I35: {=_xlfn.IFS(F35=H35,1,F35=G35,0,F35<>G35,(F35-G35)/(G35))} -> 0 | J35: =VLOOKUP($E35,статьи!$G$2:$I$24,2,) -> Манипулирование рынком, если это действие не содержит уголовно наказуемого деяния
A36: 34 | B36: 19.01.2026 | C36: Тихомиров Вадим Владимирович | D36: Гражданин | E36: ст.15.30 КоАП РФ | F36: 3000 | G36: 3000 | H36: 5000 | I36: {=_xlfn.IFS(F36=H36,1,F36=G36,0,F36<>G36,(F36-G36)/(G36))} -> 0 | J36: =VLOOKUP($E36,статьи!$G$2:$I$24,2,) -> Манипулирование рынком, если это действие не содержит уголовно наказуемого деяния
A37: 35 | B37: 15.01.2026 | C37: ООО "Тринити Шиппинг" | D37: Юридическое лицо | E37: ст.15.30 КоАП РФ | F37: 700000 | G37: 700000 | H37: в размере суммы излишнего дохода… но не менее 700 000 рублей | I37: {=_xlfn.IFS(F37=H37,1,F37=G37,0,F37<>G37,(F37-G37)/(G37))} -> 0 | J37: =VLOOKUP($E37,статьи!$G$2:$I$24,2,) -> Манипулирование рынком, если это действие не содержит уголовно наказуемого деяния
A38: 36 | B38: 15.01.2026 | C38: Бурыкин Иван Терентьевич | D38: Гражданин | E38: ст.15.30 КоАП РФ | F38: 3000 | G38: 3000 | H38: 5000 | I38: {=_xlfn.IFS(F38=H38,1,F38=G38,0,F38<>G38,(F38-G38)/(G38))} -> 0 | J38: =VLOOKUP($E38,статьи!$G$2:$I$24,2,) -> Манипулирование рынком, если это действие не содержит уголовно наказуемого деяния
A39: 37 | B39: 13.01.2026 | C39: Колесникова Надежда Вячеславовна | D39: Гражданин | E39: ст.15.30 КоАП РФ | F39: 3000 | G39: 3000 | H39: 5000 | I39: {=_xlfn.IFS(F39=H39,1,F39=G39,0,F39<>G39,(F39-G39)/(G39))} -> 0 | J39: =VLOOKUP($E39,статьи!$G$2:$I$24,2,) -> Манипулирование рынком, если это действие не содержит уголовно наказуемого деяния
A40: 38 | B40: 13.01.2026 | C40: Мазнев Андрей Вячеславович | D40: Гражданин | E40: ст.15.30 КоАП РФ | F40: 3000 | G40: 3000 | H40: 5000 | I40: {=_xlfn.IFS(F40=H40,1,F40=G40,0,F40<>G40,(F40-G40)/(G40))} -> 0 | J40: =VLOOKUP($E40,статьи!$G$2:$I$24,2,) -> Манипулирование рынком, если это действие не содержит уголовно наказуемого деяния
...

Sheet статьи
G2: статья | H2: содержание | I2: ссылка
G3: ч.9 ст.15.29 КоАП РФ | H3: Воспрепятствование профессиональным участником рынка ценных бумаг, клиринговой организацией, лицом, осуществляющим функции центрального контрагента, акционерным инвестиционным фондом, негосударственным пенсионным фондом, управляющей компанией акционерного инвестиционного фонда, паевого инвестиционного фонда или негосударственного пенсионного фонда либо специализированным депозитарием акционерного инвестиционного фонда, паевого инвестиционного фонда или негосударственного пенсионного фонда проведению Банком России проверок либо неисполнение или ненадлежащее исполнение предписаний Банка России | I3: 15.29
G4: ч.6 ст.15.29 КоАП РФ | H4: Нарушение управляющей компанией акционерного инвестиционного фонда или паевого инвестиционного фонда предусмотренных федеральными законами и иными нормативными правовыми актами Российской Федерации ограничений ее деятельности - | I4: 15.29
G5: ч.12 ст.15.29 КоАП РФ | H5: Иное нарушение профессиональным участником рынка ценных бумаг, репозитарием, клиринговой организацией, лицом, осуществляющим функции центрального контрагента, акционерным инвестиционным фондом, негосударственным пенсионным фондом, управляющей компанией акционерного инвестиционного фонда, паевого инвестиционного фонда или негосударственного пенсионного фонда либо специализированным депозитарием акционерного инвестиционного фонда, паевого инвестиционного фонда или негосударственного пенсионного фонда при осуществлении ими соответствующих видов деятельности установленных законодательством требований к этим видам деятельности, за исключением случаев, предусмотренных частями 1 - 11 настоящей статьи, статьями 13.25, 15.18 - 15.20, 15.22, 15.23.1, 15.24.1, 15.30 и 19.7.3 настоящего Кодекса | I5: 15.29
G6: ч.5 ст.15.29 КоАП РФ | H6: Нарушение установленных нормативными правовыми актами Российской Федерации и инвестиционной декларацией акционерного инвестиционного фонда или паевого инвестиционного фонда требований к составу активов акционерных инвестиционных фондов или паевых инвестиционных фондов либо неустранение нарушений в структуре активов акционерных инвестиционных фондов или паевых инвестиционных фондов - | I6: 15.29
G7: ст.15.30 КоАП РФ | H7: Манипулирование рынком, если это действие не содержит уголовно наказуемого деяния | I7: 15.30
G8: ч.9 ст.19.5 КоАП РФ | H8: 9. Невыполнение в установленный срок законного предписания Банка России, за исключением случаев, предусмотренных частью 9.1 настоящей статьи, - | I8: 19.5
G9: ч.1 ст.19.7.3 КоАП РФ | H9: 1. Непредставление или нарушение порядка либо сроков представления в Банк России отчетов, уведомлений и иной информации, предусмотренной законодательством и (или) необходимой для осуществления этим органом (должностным лицом) его законной деятельности, либо представление информации не в полном объеме и (или) недостоверной информации, за исключением случаев, если в соответствии со страховым законодательством, законодательством Российской Федерации о кредитной кооперации, о сельскохозяйственной кооперации, о микрофинансовой деятельности и микрофинансовых организациях или о ломбардах Банком России дается законное предписание об устранении нарушения страхового законодательства, законодательства Российской Федерации о кредитной кооперации, о сельскохозяйственной кооперации, о микрофинансовой деятельности и микрофинансовых организациях или о ломбардах, и случаев, указанных в части 2 настоящей статьи, если эти действия (бездействие) не содержат признаков уголовно наказуемого деяния | I9: 19,7,3
G10: ч.2 ст.15.19 КоАП РФ | H10: 2. Нераскрытие или нарушение эмитентом, профессиональным участником рынка ценных бумаг, клиринговой организацией, акционерным инвестиционным фондом, управляющей компанией акционерного инвестиционного фонда, паевого инвестиционного фонда или негосударственного пенсионного фонда, специализированным депозитарием акционерного инвестиционного фонда, паевого инвестиционного фонда или негосударственного пенсионного фонда либо лицом, оказывающим услуги по публичному представлению раскрываемой информации, порядка и сроков раскрытия информации, предусмотренной федеральными законами и принятыми в соответствии с ними иными нормативными правовыми актами, а равно раскрытие информации не в полном объеме, и (или) недостоверной информации, и (или) вводящей в заблуждение информации | I10: 15.19
G11: ч.2 ст.15.29 КоАП РФ | H11: Нарушение профессиональным участником рынка ценных бумаг, осуществляющим брокерскую или дилерскую деятельность либо деятельность по управлению ценными бумагами, установленных нормативными правовыми актами Российской Федерации правил ведения учета и составления отчетности | I11: 15.29
G12: ч.7 ст.15.29 КоАП РФ | H12: Неисполнение или ненадлежащее исполнение специализированным депозитарием акционерного инвестиционного фонда, паевого инвестиционного фонда или негосударственного пенсионного фонда установленных федеральными законами и иными нормативными правовыми актами Российской Федерации обязанностей по учету и хранению имущества, а также по осуществлению контроля за распоряжением имуществом, за исключением случая, предусмотренного частью 8 настоящей статьи | I12: 15.29
G13: ст.14.30 КоАП РФ | H13: Нарушение бюро кредитных историй установленного порядка сбора, хранения, защиты и обработки сведений, составляющих кредитную историю | I13: 14.30
G14: ч.2 ст.5.54 КоАП РФ | H14: 2. Незаконный отказ бюро кредитных историй в исправлении недостоверной информации или неисполнение обязанности по исправлению недостоверной информации, содержащейся в кредитной истории (кредитном отчете) | I14: 5.54
G15: ч.1 ст.5.54 КоАП РФ | H15: 1. Непроведение проверки или несвоевременное проведение по требованию субъекта кредитной истории проверки бюро кредитных историй информации, содержащейся в кредитной истории (кредитном отчете) | I15: 5.54
G16: ч.4 ст.15.35 КоАП РФ | H16: 4. Неисполнение или ненадлежащее исполнение лицом обязанностей по принятию установленных законодательством мер, направленных на предотвращение, выявление и пресечение злоупотреблений на финансовых и товарных рынках | I16: 15.35
G17: ч.2 ст.15.35 КоАП РФ | H17: 2. Неисполнение или ненадлежащее исполнение лицами, обязанными вести список инсайдеров, обязанностей по ведению списка инсайдеров и уведомлению лиц, включенных в список инсайдеров. | I17: 15.35
G18: ч.7 ст.14.24 КоАП РФ | H18: 7. Нарушение организатором торговли правил организованных торгов, зарегистрированных в установленном законодательством об организованных торгах порядке | I18: 14.24
G19: ст.15.21 КоАП РФ | H19: Неправомерное использование инсайдерской информации, если это действие не содержит уголовно наказуемого деяния | I19: 15.21
G20: ст.5.55 КоАП РФ | H20: Непредоставление бюро кредитных историй кредитного отчета, предоставление неполного или недостоверного кредитного отчета, а также несвоевременное предоставление кредитного отчета в случаях, если такое предоставление осуществляется или должно осуществляться в соответствии с Федеральным законом "О кредитных историях" | I20: 5.55
... G24: ч.1 ст.13.25 КоАП РФ | H24: 1. Неисполнение акционерным обществом, профессиональным участником рынка ценных бумаг, управляющей компанией акционерного инвестиционного фонда, паевого инвестиционного фонда или негосударственного пенсионного фонда либо специализированным депозитарием акционерного инвестиционного фонда, паевого инвестиционного фонда или негосударственного пенсионного фонда обязанности по хранению документов, которые предусмотрены законодательством об акционерных обществах, о рынке ценных бумаг, об инвестиционных фондах и принятыми в соответствии с ним нормативными правовыми актами и хранение которых является обязательным, а также нарушение установленных порядка и сроков хранения таких документов | I24: 13.25

Sheet дашборды
A2: Тип лица | B2: (Все) | C2: указать год, проблема с объединением янв 2025 и 2026 года
A3: Штраф факт | B3: (Все)
A5: Названия строк | B5: Количество по полю Штраф факт
A6: 2025 | B6: 387
A7: янв | B7: 17
A8: февр | B8: 20
A9: март | B9: 33
A10: апр | B10: 33
A11: май | B11: 36
A12: июнь | B12: 22
A13: июль | B13: 29
A14: авг | B14: 31
A15: сент | B15: 24
A16: окт | B16: 51
A17: нояб | B17: 61
... A22: Общий итог | B22: 449
C23: объеденить самые нечастые и указать что их доля крайне мала, тоже круговая | N23: Штраф факт | O23: (Все)
N24: Тип лица | O24: Юридическое лицо | X24: в прочие входят
N26: Названия строк | O26: Количество по полю Штраф факт | X26: ч.6 ст.15.29 КоАП РФ | Y26: 10
A27: Тип лица | B27: Юридическое лицо | N27: ч.12 ст.15.29 КоАП РФ | O27: 68 | X27: ч.1 ст.5.54 КоАП РФ | Y27: 9
A28: Штраф факт | B28: (Все) | N28: Прочие ≤10 | O28: 46 | X28: ст.15.30 КоАП РФ | Y28: 5
N29: ч.9 ст.15.29 КоАП РФ | O29: 29 | X29: ч.5 ст.15.29 КоАП РФ | Y29: 5
A30: Названия строк | B30: Количество по полю Штраф факт | N30: ч.1 ст.19.7.3 КоАП РФ | O30: 28 | X30: ст.14.30 КоАП РФ | Y30: 3
A31: ч.12 ст.15.29 КоАП РФ | B31: 68 | N31: ч.2 ст.15.19 КоАП РФ | O31: 23 | X31: ст.5.55 КоАП РФ | Y31: 3
A32: ч.9 ст.15.29 КоАП РФ | B32: 29 | N32: ч.2 ст.15.29 КоАП РФ | O32: 23 | X32: ч.7 ст.15.29 КоАП РФ | Y32: 2
A33: ч.1 ст.19.7.3 КоАП РФ | B33: 28 | N33: ч.9 ст.19.5 КоАП РФ | O33: 20 | X33: ч.7 ст.14.24 КоАП РФ | Y33: 2
A34: ч.2 ст.15.19 КоАП РФ | B34: 23 | N34: Общий итог | O34: 237 | X34: ч.2 ст.15.35 КоАП РФ | Y34: 1
A35: ч.2 ст.15.29 КоАП РФ | B35: 23 | X35: ч.10 ст.15.29 КоАП РФ | Y35: 1
A36: ч.9 ст.19.5 КоАП РФ | B36: 20 | X36: ч.2 ст.5.54 КоАП РФ | Y36: 1
A37: ч.6 ст.15.29 КоАП РФ | B37: 10 | X37: ч.4 ст.15.35 КоАП РФ | Y37: 1
A38: ч.1 ст.5.54 КоАП РФ | B38: 9 | X38: ст.14.29 КоАП РФ | Y38: 1
A39: ст.15.30 КоАП РФ | B39: 5 | X39: ч.1 ст.13.25 КоАП РФ | Y39: 1
A40: ч.5 ст.15.29 КоАП РФ | B40: 5 | X40: ч.4 ст.15.19 КоАП РФ | Y40: 1
A41: ст.14.30 КоАП РФ | B41: 3
A42: ст.5.55 КоАП РФ | B42: 3
A43: ч.7 ст.15.29 КоАП РФ | B43: 2
A44: ч.7 ст.14.24 КоАП РФ | B44: 2
A45: ч.2 ст.15.35 КоАП РФ | B45: 1 | N45: Названия строк | O45: Сумма по полю Штраф факт
A46: ч.10 ст.15.29 КоАП РФ | B46: 1 | N46: Должностное лицо | O46: 30000
A47: ч.2 ст.5.54 КоАП РФ | B47: 1 | N47: Гражданин | O47: 821000
...

Sheet впр
B1: Статья | C1: Тип лица | D1: Мин штраф | E1: Макс штраф
A2: =B2&C2 -> ч.9 ст.15.29 КоАП РФЮридическое лицо | B2: ч.9 ст.15.29 КоАП РФ | C2: Юридическое лицо | D2: 700000 | E2: 1000000
A3: =B3&C3 -> ч.9 ст.15.29 КоАП РФДолжностное лицо | B3: ч.9 ст.15.29 КоАП РФ | C3: Должностное лицо | D3: 30000 | E3: 50000
A4: =B4&C4 -> ч.6 ст.15.29 КоАП РФЮридическое лицо | B4: ч.6 ст.15.29 КоАП РФ | C4: Юридическое лицо | D4: 700000 | E4: 1000000
A5: =B5&C5 -> ч.6 ст.15.29 КоАП РФДолжностное лицо | B5: ч.6 ст.15.29 КоАП РФ | C5: Должностное лицо | D5: 30000 | E5: 50000
A6: =B6&C6 -> ч.12 ст.15.29 КоАП РФГражданин | B6: ч.12 ст.15.29 КоАП РФ | C6: Гражданин | D6: 1000 | E6: 3000
A7: =B7&C7 -> ч.12 ст.15.29 КоАП РФДолжностное лицо | B7: ч.12 ст.15.29 КоАП РФ | C7: Должностное лицо | D7: 10000 | E7: 20000
A8: =B8&C8 -> ч.12 ст.15.29 КоАП РФЮридическое лицо | B8: ч.12 ст.15.29 КоАП РФ | C8: Юридическое лицо | D8: 300000 | E8: 500000
A9: =B9&C9 -> ч.5 ст.15.29 КоАП РФДолжностное лицо | B9: ч.5 ст.15.29 КоАП РФ | C9: Должностное лицо | D9: 20000 | E9: 30000
A10: =B10&C10 -> ч.5 ст.15.29 КоАП РФЮридическое лицо | B10: ч.5 ст.15.29 КоАП РФ | C10: Юридическое лицо | D10: 500000 | E10: 700000
A11: =B11&C11 -> ч.2 ст.15.29 КоАП РФДолжностное лицо | B11: ч.2 ст.15.29 КоАП РФ | C11: Должностное лицо | D11: 20000 | E11: 30000
A12: =B12&C12 -> ч.2 ст.15.29 КоАП РФЮридическое лицо | B12: ч.2 ст.15.29 КоАП РФ | C12: Юридическое лицо | D12: 500000 | E12: 700000
A13: =B13&C13 -> ч.7 ст.15.29 КоАП РФДолжностное лицо | B13: ч.7 ст.15.29 КоАП РФ | C13: Должностное лицо | D13: 20000 | E13: 30000
... A18: =B18&C18 -> ст.15.30 КоАП РФДолжностное лицо | B18: ст.15.30 КоАП РФ | C18: Должностное лицо | D18: 30000 | E18: 50000
A19: =B19&C19 -> ст.15.30 КоАП РФЮридическое лицо | B19: ст.15.30 КоАП РФ | C19: Юридическое лицо | D19: 700000 | E19: в размере суммы излишнего дохода… но не менее 700 000 рублей
A20: =B20&C20 -> ч.9 ст.19.5 КоАП РФДолжностное лицо | B20: ч.9 ст.19.5 КоАП РФ | C20: Должностное лицо | D20: 20000 | E20: 30000
A21: =B21&C21 -> ч.9 ст.19.5 КоАП РФЮридическое лицо | B21: ч.9 ст.19.5 КоАП РФ | C21: Юридическое лицо | D21: 500000 | E21: 700000
A22: =B22&C22 -> ч.1 ст.19.7.3 КоАП РФГражданин | B22: ч.1 ст.19.7.3 КоАП РФ | C22: Гражданин | D22: 2000 | E22: 4000
A23: =B23&C23 -> ч.1 ст.19.7.3 КоАП РФДолжностное лицо | B23: ч.1 ст.19.7.3 КоАП РФ | C23: Должностное лицо | D23: 20000 | E23: 30000
A24: =B24&C24 -> ч.1 ст.19.7.3 КоАП РФЮридическое лицо | B24: ч.1 ст.19.7.3 КоАП РФ | C24: Юридическое лицо | D24: 500000 | E24: 700000
A25: =B25&C25 -> ч.2 ст.15.19 КоАП РФДолжностное лицо | B25: ч.2 ст.15.19 КоАП РФ | C25: Должностное лицо | D25: 30000 | E25: 50000
A26: =B26&C26 -> ч.2 ст.15.19 КоАП РФЮридическое лицо | B26: ч.2 ст.15.19 КоАП РФ | C26: Юридическое лицо | D26: 700000 | E26: 1000000
A27: =B27&C27 -> ч.4 ст.15.19 КоАП РФДолжностное лицо | B27: ч.4 ст.15.19 КоАП РФ | C27: Должностное лицо | D27: 20000 | E27: 30000
A28: =B28&C28 -> ч.4 ст.15.19 КоАП РФЮридическое лицо | B28: ч.4 ст.15.19 КоАП РФ | C28: Юридическое лицо | D28: 300000 | E28: 500000
A29: =B29&C29 -> ст.14.30 КоАП РФДолжностное лицо | B29: ст.14.30 КоАП РФ | C29: Должностное лицо | D29: 2500 | E29: 5000
A30: =B30&C30 -> ст.14.30 КоАП РФЮридическое лицо | B30: ст.14.30 КоАП РФ | C30: Юридическое лицо | D30: 10000 | E30: 20000
A31: =B31&C31 -> ч.2 ст.5.54 КоАП РФДолжностное лицо | B31: ч.2 ст.5.54 КоАП РФ | C31: Должностное лицо | D31: 2000 | E31: 5000
... A42: =B42&C42 -> ст.15.21 КоАП РФДолжностное лицо | B42: ст.15.21 КоАП РФ | C42: Должностное лицо | D42: 30000 | E42: 50000
A43: =B43&C43 -> ст.15.21 КоАП РФЮридическое лицо | B43: ст.15.21 КоАП РФ | C43: Юридическое лицо | D43: 700000 | E43: в размере суммы излишнего дохода… но не менее 700 000 рублей
A44: =B44&C44 -> ст.5.55 КоАП РФДолжностное лицо | B44: ст.5.55 КоАП РФ | C44: Должностное лицо | D44: 1000 | E44: 2500
A45: =B45&C45 -> ст.5.55 КоАП РФЮридическое лицо | B45: ст.5.55 КоАП РФ | C45: Юридическое лицо | D45: 20000 | E45: 50000
A46: =B46&C46 -> ст.14.29 КоАП РФГражданин | B46: ст.14.29 КоАП РФ | C46: Гражданин | D46: 1000 | E46: 2500
A47: =B47&C47 -> ст.14.29 КоАП РФДолжностное лицо | B47: ст.14.29 КоАП РФ | C47: Должностное лицо | D47: 2500 | E47: 5000
A48: =B48&C48 -> ст.14.29 КоАП РФЮридическое лицо | B48: ст.14.29 КоАП РФ | C48: Юридическое лицо | D48: 30000 | E48: 50000
A49: =B49&C49 -> ч.1 ст.13.25 КоАП РФДолжностное лицо | B49: ч.1 ст.13.25 КоАП РФ | C49: Должностное лицо | D49: 2500 | E49: 5000
A50: =B50&C50 -> ч.1 ст.13.25 КоАП РФЮридическое лицо | B50: ч.1 ст.13.25 КоАП РФ | C50: Юридическое лицо | D50: 200000 | E50: 300000

Sheet копия
A1: Номер случая | B1: Дата постановления | C1: Субъект | D1: Тип лица | E1: Статья КоАП | F1: Штраф факт | G1: мин | H1: макс | I1: Превышышение над мин размером %/min | J1: вид штрафа
A2: 1 | B2: 46070 | C2: Акционерное общество «Негосударственный пенсионный фонд «Ростех» | D2: Юридическое лицо | E2: ч.9 ст.15.29 КоАП РФ | F2: 700000 | G2: 700000 | H2: 1000000 | I2: {=_xlfn.IFS(F2=H2,1,F2=G2,0,F2<>G2,(F2-G2)/(G2))} -> 0 | J2: =IF(ISERROR(I2),"Предупреждение", IF(I2<0,"Ниже минимума", IF(I2=0,"Минимум", IF(I2<1,"В диапазоне", IF(I2=1,"Максимум", "Выше максимума"))))) -> Минимум
A3: 2 | B3: 46070 | C3: Общество с ограниченной ответственностью «Управляющая компания_x000D_ «Атон-менеджмент» | D3: Юридическое лицо | E3: ч.6 ст.15.29 КоАП РФ | F3: 700000 | G3: 700000 | H3: 1000000 | I3: {=_xlfn.IFS(F3=H3,1,F3=G3,0,F3<>G3,(F3-G3)/(G3))} -> 0 | J3: =IF(ISERROR(I3),"Предупреждение", IF(I3<0,"Ниже минимума", IF(I3=0,"Минимум", IF(I3<1,"В диапазоне", IF(I3=1,"Максимум", "Выше максимума"))))) -> Минимум
A4: 2 | B4: 46070 | C4: Общество с ограниченной ответственностью «Управляющая компания_x000D_ «Атон-менеджмент» | D4: Юридическое лицо | E4: ч.12 ст.15.29 КоАП РФ | F4: 320000 | G4: 300000 | H4: 500000 | I4: {=_xlfn.IFS(F4=H4,1,F4=G4,0,F4<>G4,(F4-G4)/(G4))} -> 0.066666667 | J4: =IF(ISERROR(I4),"Предупреждение", IF(I4<0,"Ниже минимума", IF(I4=0,"Минимум", IF(I4<1,"В диапазоне", IF(I4=1,"Максимум", "Выше максимума"))))) -> В диапазоне
A5: 3 | B5: 46066 | C5: Акционерное общество_x000D_ Управляющая компания «Центр Эссет Менеджмент» | D5: Юридическое лицо | E5: ч.12 ст.15.29 КоАП РФ | F5: предупреждение | G5: 300000 | H5: 500000 | I5: {=_xlfn.IFS(F5=H5,1,F5=G5,0,F5<>G5,(F5-G5)/(G5))} -> #VALUE! | J5: =IF(ISERROR(I5),"Предупреждение", IF(I5<0,"Ниже минимума", IF(I5=0,"Минимум", IF(I5<1,"В диапазоне", IF(I5=1,"Максимум", "Выше максимума"))))) -> Предупреждение
A6: 4 | B6: 46063 | C6: АО «ИК «РИКОМ-ТРАСТ» | D6: Юридическое лицо | E6: ч.9 ст.15.29 КоАП РФ | F6: 1000000 | G6: 700000 | H6: 1000000 | I6: {=_xlfn.IFS(F6=H6,1,F6=G6,0,F6<>G6,(F6-G6)/(G6))} -> 1 | J6: =IF(ISERROR(I6),"Предупреждение", IF(I6<0,"Ниже минимума", IF(I6=0,"Минимум", IF(I6<1,"В диапазоне", IF(I6=1,"Максимум", "Выше максимума"))))) -> Максимум
A7: 5 | B7: 46063 | C7: Акционерное общество ВИМ Инвестиции | D7: Юридическое лицо | E7: ч.12 ст.15.29 КоАП РФ | F7: 350000 | G7: 300000 | H7: 500000 | I7: {=_xlfn.IFS(F7=H7,1,F7=G7,0,F7<>G7,(F7-G7)/(G7))} -> 0.16666667 | J7: =IF(ISERROR(I7),"Предупреждение", IF(I7<0,"Ниже минимума", IF(I7=0,"Минимум", IF(I7<1,"В диапазоне", IF(I7=1,"Максимум", "Выше максимума"))))) -> В диапазоне
A8: 6 | B8: 46063 | C8: Общество с ограниченной_x000D_ ответственностью_x000D_ «Управляющая компания_x000D_ «Ресурс» | D8: Юридическое лицо | E8: ч.6 ст.15.29 КоАП РФ | F8: предупреждение | G8: 700000 | H8: 1000000 | I8: {=_xlfn.IFS(F8=H8,1,F8=G8,0,F8<>G8,(F8-G8)/(G8))} -> #VALUE! | J8: =IF(ISERROR(I8),"Предупреждение", IF(I8<0,"Ниже минимума", IF(I8=0,"Минимум", IF(I8<1,"В диапазоне", IF(I8=1,"Максимум", "Выше максимума"))))) -> Предупреждение
A9: 7 | B9: 46063 | C9: Общество с ограниченной ответственностью «ТрастЮнион Эссет Менеджмент» | D9: Юридическое лицо | E9: ч.12 ст.15.29 КоАП РФ | F9: предупреждение | G9: 300000 | H9: 500000 | I9: {=_xlfn.IFS(F9=H9,1,F9=G9,0,F9<>G9,(F9-G9)/(G9))} -> #VALUE! | J9: =IF(ISERROR(I9),"Предупреждение", IF(I9<0,"Ниже минимума", IF(I9=0,"Минимум", IF(I9<1,"В диапазоне", IF(I9=1,"Максимум", "Выше максимума"))))) -> Предупреждение
A10: 8 | B10: 46063 | C10: Акционерное общество «Управляющая Компания ТРИНФИКО» | D10: Юридическое лицо | E10: ч.5 ст.15.29 КоАП РФ | F10: 250000 | G10: 500000 | H10: 700000 | I10: {=_xlfn.IFS(F10=H10,1,F10=G10,0,F10<>G10,(F10-G10)/(G10))} -> -0.5 | J10: =IF(ISERROR(I10),"Предупреждение", IF(I10<0,"Ниже минимума", IF(I10=0,"Минимум", IF(I10<1,"В диапазоне", IF(I10=1,"Максимум", "Выше максимума"))))) -> Ниже минимума
A11: 9 | B11: 46062 | C11: ООО «Цифра брокер» | D11: Юридическое лицо | E11: ч.12 ст.15.29 КоАП РФ | F11: 300000 | G11: 300000 | H11: 500000 | I11: {=_xlfn.IFS(F11=H11,1,F11=G11,0,F11<>G11,(F11-G11)/(G11))} -> 0 | J11: =IF(ISERROR(I11),"Предупреждение", IF(I11<0,"Ниже минимума", IF(I11=0,"Минимум", IF(I11<1,"В диапазоне", IF(I11=1,"Максимум", "Выше максимума"))))) -> Минимум
A12: 10 | B12: 46059 | C12: Голубков Виктор Владимирович | D12: Гражданин | E12: ст.15.30 КоАП РФ | F12: 3000 | G12: 3000 | H12: 5000 | I12: {=_xlfn.IFS(F12=H12,1,F12=G12,0,F12<>G12,(F12-G12)/(G12))} -> 0 | J12: =IF(ISERROR(I12),"Предупреждение", IF(I12<0,"Ниже минимума", IF(I12=0,"Минимум", IF(I12<1,"В диапазоне", IF(I12=1,"Максимум", "Выше максимума"))))) -> Минимум
A13: 11 | B13: 46059 | C13: генеральный директор общества с ограниченной ответственностью «Тринити Шиппинг» Ярошенко Александр Иванович | D13: Должностное лицо | E13: ст.15.30 КоАП РФ | F13: 30000 | G13: 30000 | H13: 50000 | I13: {=_xlfn.IFS(F13=H13,1,F13=G13,0,F13<>G13,(F13-G13)/(G13))} -> 0 | J13: =IF(ISERROR(I13),"Предупреждение", IF(I13<0,"Ниже минимума", IF(I13=0,"Минимум", IF(I13<1,"В диапазоне", IF(I13=1,"Максимум", "Выше максимума"))))) -> Минимум
A14: 12 | B14: 46059 | C14: Гальямова Наталья Александровна | D14: Гражданин | E14: ст.15.30 КоАП РФ | F14: 3000 | G14: 3000 | H14: 5000 | I14: {=_xlfn.IFS(F14=H14,1,F14=G14,0,F14<>G14,(F14-G14)/(G14))} -> 0 | J14: =IF(ISERROR(I14),"Предупреждение", IF(I14<0,"Ниже минимума", IF(I14=0,"Минимум", IF(I14<1,"В диапазоне", IF(I14=1,"Максимум", "Выше максимума"))))) -> Минимум
A15: 13 | B15: 46056 | C15: Чмыхало Юлия Анатольевна | D15: Гражданин | E15: ст.15.30 КоАП РФ | F15: 3000 | G15: 3000 | H15: 5000 | I15: {=_xlfn.IFS(F15=H15,1,F15=G15,0,F15<>G15,(F15-G15)/(G15))} -> 0 | J15: =IF(ISERROR(I15),"Предупреждение", IF(I15<0,"Ниже минимума", IF(I15=0,"Минимум", IF(I15<1,"В диапазоне", IF(I15=1,"Максимум", "Выше максимума"))))) -> Минимум
A16: 14 | B16: 46052 | C16: Усольцева Яна Германовна | D16: Гражданин | E16: ст.15.30 КоАП РФ | F16: 3000 | G16: 3000 | H16: 5000 | I16: {=_xlfn.IFS(F16=H16,1,F16=G16,0,F16<>G16,(F16-G16)/(G16))} -> 0 | J16: =IF(ISERROR(I16),"Предупреждение", IF(I16<0,"Ниже минимума", IF(I16=0,"Минимум", IF(I16<1,"В диапазоне", IF(I16=1,"Максимум", "Выше максимума"))))) -> Минимум
A17: 15 | B17: 46052 | C17: Краснова Галина Ивановна | D17: Гражданин | E17: ст.15.30 КоАП РФ | F17: 3000 | G17: 3000 | H17: 5000 | I17: {=_xlfn.IFS(F17=H17,1,F17=G17,0,F17<>G17,(F17-G17)/(G17))} -> 0 | J17: =IF(ISERROR(I17),"Предупреждение", IF(I17<0,"Ниже минимума", IF(I17=0,"Минимум", IF(I17<1,"В диапазоне", IF(I17=1,"Максимум", "Выше максимума"))))) -> Минимум
A18: 16 | B18: 46052 | C18: Артамонов Валерий Геннадьевич | D18: Гражданин | E18: ст.15.30 КоАП РФ | F18: 3000 | G18: 3000 | H18: 5000 | I18: {=_xlfn.IFS(F18=H18,1,F18=G18,0,F18<>G18,(F18-G18)/(G18))} -> 0 | J18: =IF(ISERROR(I18),"Предупреждение", IF(I18<0,"Ниже минимума", IF(I18=0,"Минимум", IF(I18<1,"В диапазоне", IF(I18=1,"Максимум", "Выше максимума"))))) -> Минимум
A19: 17 | B19: 46052 | C19: Манюкова Татьяна Васильевна | D19: Гражданин | E19: ст.15.30 КоАП РФ | F19: 3000 | G19: 3000 | H19: 5000 | I19: {=_xlfn.IFS(F19=H19,1,F19=G19,0,F19<>G19,(F19-G19)/(G19))} -> 0 | J19: =IF(ISERROR(I19),"Предупреждение", IF(I19<0,"Ниже минимума", IF(I19=0,"Минимум", IF(I19<1,"В диапазоне", IF(I19=1,"Максимум", "Выше максимума"))))) -> Минимум
A20: 18 | B20: 46052 | C20: Доценко Марина Сергеевна | D20: Гражданин | E20: ст.15.30 КоАП РФ | F20: 3000 | G20: 3000 | H20: 5000 | I20: {=_xlfn.IFS(F20=H20,1,F20=G20,0,F20<>G20,(F20-G20)/(G20))} -> 0 | J20: =IF(ISERROR(I20),"Предупреждение", IF(I20<0,"Ниже минимума", IF(I20=0,"Минимум", IF(I20<1,"В диапазоне", IF(I20=1,"Максимум", "Выше максимума"))))) -> Минимум
A21: 19 | B21: 46052 | C21: Гальямов Марсель Геральдович | D21: Гражданин | E21: ст.15.30 КоАП РФ | F21: 3000 | G21: 3000 | H21: 5000 | I21: {=_xlfn.IFS(F21=H21,1,F21=G21,0,F21<>G21,(F21-G21)/(G21))} -> 0 | J21: =IF(ISERROR(I21),"Предупреждение", IF(I21<0,"Ниже минимума", IF(I21=0,"Минимум", IF(I21<1,"В диапазоне", IF(I21=1,"Максимум", "Выше максимума"))))) -> Минимум
... A36: 34 | B36: 46041 | C36: Тихомиров Вадим Владимирович | D36: Гражданин | E36: ст.15.30 КоАП РФ | F36: 3000 | G36: 3000 | H36: 5000 | I36: {=_xlfn.IFS(F36=H36,1,F36=G36,0,F36<>G36,(F36-G36)/(G36))} -> 0 | J36: =IF(ISERROR(I36),"Предупреждение", IF(I36<0,"Ниже минимума", IF(I36=0,"Минимум", IF(I36<1,"В диапазоне", IF(I36=1,"Максимум", "Выше максимума"))))) -> Минимум
A37: 35 | B37: 46037 | C37: ООО "Тринити Шиппинг" | D37: Юридическое лицо | E37: ст.15.30 КоАП РФ | F37: 700000 | G37: 700000 | H37: в размере суммы излишнего дохода… но не менее 700 000 рублей | I37: {=_xlfn.IFS(F37=H37,1,F37=G37,0,F37<>G37,(F37-G37)/(G37))} -> 0 | J37: =IF(ISERROR(I37),"Предупреждение", IF(I37<0,"Ниже минимума", IF(I37=0,"Минимум", IF(I37<1,"В диапазоне", IF(I37=1,"Максимум", "Выше максимума"))))) -> Минимум
A38: 36 | B38: 46037 | C38: Бурыкин Иван Терентьевич | D38: Гражданин | E38: ст.15.30 КоАП РФ | F38: 3000 | G38: 3000 | H38: 5000 | I38: {=_xlfn.IFS(F38=H38,1,F38=G38,0,F38<>G38,(F38-G38)/(G38))} -> 0 | J38: =IF(ISERROR(I38),"Предупреждение", IF(I38<0,"Ниже минимума", IF(I38=0,"Минимум", IF(I38<1,"В диапазоне", IF(I38=1,"Максимум", "Выше максимума"))))) -> Минимум
A39: 37 | B39: 46035 | C39: Колесникова Надежда Вячеславовна | D39: Гражданин | E39: ст.15.30 КоАП РФ | F39: 3000 | G39: 3000 | H39: 5000 | I39: {=_xlfn.IFS(F39=H39,1,F39=G39,0,F39<>G39,(F39-G39)/(G39))} -> 0 | J39: =IF(ISERROR(I39),"Предупреждение", IF(I39<0,"Ниже минимума", IF(I39=0,"Минимум", IF(I39<1,"В диапазоне", IF(I39=1,"Максимум", "Выше максимума"))))) -> Минимум
A40: 38 | B40: 46035 | C40: Мазнев Андрей Вячеславович | D40: Гражданин | E40: ст.15.30 КоАП РФ | F40: 3000 | G40: 3000 | H40: 5000 | I40: {=_xlfn.IFS(F40=H40,1,F40=G40,0,F40<>G40,(F40-G40)/(G40))} -> 0 | J40: =IF(ISERROR(I40),"Предупреждение", IF(I40<0,"Ниже минимума", IF(I40=0,"Минимум", IF(I40<1,"В диапазоне", IF(I40=1,"Максимум", "Выше максимума"))))) -> Минимум
A41: 39 | B41: 46035 | C41: Мазнев Сергей Вячеславович | D41: Гражданин | E41: ст.15.30 КоАП РФ | F41: 3000 | G41: 3000 | H41: 5000 | I41: {=_xlfn.IFS(F41=H41,1,F41=G41,0,F41<>G41,(F41-G41)/(G41))} -> 0 | J41: =IF(ISERROR(I41),"Предупреждение", IF(I41<0,"Ниже минимума", IF(I41=0,"Минимум", IF(I41<1,"В диапазоне", IF(I41=1,"Максимум", "Выше максимума"))))) -> Минимум
A42: 40 | B42: 46035 | C42: Дмитриев Андрей Николаевич | D42: Гражданин | E42: ст.15.30 КоАП РФ | F42: 3000 | G42: 3000 | H42: 5000 | I42: {=_xlfn.IFS(F42=H42,1,F42=G42,0,F42<>G42,(F42-G42)/(G42))} -> 0 | J42: =IF(ISERROR(I42),"Предупреждение", IF(I42<0,"Ниже минимума", IF(I42=0,"Минимум", IF(I42<1,"В диапазоне", IF(I42=1,"Максимум", "Выше максимума"))))) -> Минимум
A43: 41 | B43: 46035 | C43: Малык Герман Андреевич | D43: Гражданин | E43: ст.15.30 КоАП РФ | F43: 3000 | G43: 3000 | H43: 5000 | I43: {=_xlfn.IFS(F43=H43,1,F43=G43,0,F43<>G43,(F43-G43)/(G43))} -> 0 | J43: =IF(ISERROR(I43),"Предупреждение", IF(I43<0,"Ниже минимума", IF(I43=0,"Минимум", IF(I43<1,"В диапазоне", IF(I43=1,"Максимум", "Выше максимума"))))) -> Минимум
A44: 42 | B44: 46035 | C44: Усачев Андрей Николаевич | D44: Гражданин | E44: ст.15.30 КоАП РФ | F44: 3000 | G44: 3000 | H44: 5000 | I44: {=_xlfn.IFS(F44=H44,1,F44=G44,0,F44<>G44,(F44-G44)/(G44))} -> 0 | J44: =IF(ISERROR(I44),"Предупреждение", IF(I44<0,"Ниже минимума", IF(I44=0,"Минимум", IF(I44<1,"В диапазоне", IF(I44=1,"Максимум", "Выше максимума"))))) -> Минимум
A45: 43 | B45: 46035 | C45: Шушин Игорь Борисович | D45: Гражданин | E45: ст.15.30 КоАП РФ | F45: 3000 | G45: 3000 | H45: 5000 | I45: {=_xlfn.IFS(F45=H45,1,F45=G45,0,F45<>G45,(F45-G45)/(G45))} -> 0 | J45: =IF(ISERROR(I45),"Предупреждение", IF(I45<0,"Ниже минимума", IF(I45=0,"Минимум", IF(I45<1,"В диапазоне", IF(I45=1,"Максимум", "Выше максимума"))))) -> Минимум
A46: 44 | B46: 46035 | C46: Шушина Татьяна Геннадьевна | D46: Гражданин | E46: ст.15.30 КоАП РФ | F46: 3000 | G46: 3000 | H46: 5000 | I46: {=_xlfn.IFS(F46=H46,1,F46=G46,0,F46<>G46,(F46-G46)/(G46))} -> 0 | J46: =IF(ISERROR(I46),"Предупреждение", IF(I46<0,"Ниже минимума", IF(I46=0,"Минимум", IF(I46<1,"В диапазоне", IF(I46=1,"Максимум", "Выше максимума"))))) -> Минимум
A47: 45 | B47: 46035 | C47: Богачев Вячеслав Анатольевич | D47: Гражданин | E47: ст.15.30 КоАП РФ | F47: 3000 | G47: 3000 | H47: 5000 | I47: {=_xlfn.IFS(F47=H47,1,F47=G47,0,F47<>G47,(F47-G47)/(G47))} -> 0 | J47: =IF(ISERROR(I47),"Предупреждение", IF(I47<0,"Ниже минимума", IF(I47=0,"Минимум", IF(I47<1,"В диапазоне", IF(I47=1,"Максимум", "Выше максимума"))))) -> Минимум
A48: 46 | B48: 46035 | C48: Султанаева Эльвира Дамировна | D48: Гражданин | E48: ст.15.30 КоАП РФ | F48: 3000 | G48: 3000 | H48: 5000 | I48: {=_xlfn.IFS(F48=H48,1,F48=G48,0,F48<>G48,(F48-G48)/(G48))} -> 0 | J48: =IF(ISERROR(I48),"Предупреждение", IF(I48<0,"Ниже минимума", IF(I48=0,"Минимум", IF(I48<1,"В диапазоне", IF(I48=1,"Максимум", "Выше максимума"))))) -> Минимум
A49: 47 | B49: 46035 | C49: Бурыкин Иван Иванович | D49: Гражданин | E49: ст.15.30 КоАП РФ | F49: 3000 | G49: 3000 | H49: 5000 | I49: {=_xlfn.IFS(F49=H49,1,F49=G49,0,F49<>G49,(F49-G49)/(G49))} -> 0 | J49: =IF(ISERROR(I49),"Предупреждение", IF(I49<0,"Ниже минимума", IF(I49=0,"Минимум", IF(I49<1,"В диапазоне", IF(I49=1,"Максимум", "Выше максимума"))))) -> Минимум
... A53: 51 | B53: 46035 | C53: ООО «ПФЛ НОВЫЕ ИНВЕСТИЦИИ» | D53: Юридическое лицо | E53: ч.1 ст.19.7.3 КоАП РФ | F53: 350000 | G53: 500000 | H53: 700000 | I53: {=_xlfn.IFS(F53=H53,1,F53=G53,0,F53<>G53,(F53-G53)/(G53))} -> -0.3 | J53: =IF(ISERROR(I53),"Предупреждение", IF(I53<0,"Ниже минимума", IF(I53=0,"Минимум", IF(I53<1,"В диапазоне", IF(I53=1,"Максимум", "Выше максимума"))))) -> Ниже минимума
A54: 52 | B54: 46035 | C54: ООО «ТОЧКА ИНВЕСТИЦИИ» | D54: Юридическое лицо | E54: ч.1 ст.19.7.3 КоАП РФ | F54: предупреждение | G54: 500000 | H54: 700000 | I54: {=_xlfn.IFS(F54=H54,1,F54=G54,0,F54<>G54,(F54-G54)/(G54))} -> #VALUE! | J54: =IF(ISERROR(I54),"Предупреждение", IF(I54<0,"Ниже минимума", IF(I54=0,"Минимум", IF(I54<1,"В диапазоне", IF(I54=1,"Максимум", "Выше максимума"))))) -> Предупреждение
A55: 53 | B55: 46035 | C55: Акционерное общество "Частные Активы" | D55: Юридическое лицо | E55: ч.12 ст.15.29 КоАП РФ | F55: предупреждение | G55: 300000 | H55: 500000 | I55: {=_xlfn.IFS(F55=H55,1,F55=G55,0,F55<>G55,(F55-G55)/(G55))} -> #VALUE! | J55: =IF(ISERROR(I55),"Предупреждение", IF(I55<0,"Ниже минимума", IF(I55=0,"Минимум", IF(I55<1,"В диапазоне", IF(I55=1,"Максимум", "Выше максимума"))))) -> Предупреждение
A56: 54 | B56: 46035 | C56: Общество с ограниченной ответственностью Управляющая Компания "Юнион Инвест Групп" | D56: Юридическое лицо | E56: ч.9 ст.15.29 КоАП РФ | F56: 350000 | G56: 700000 | H56: 1000000 | I56: {=_xlfn.IFS(F56=H56,1,F56=G56,0,F56<>G56,(F56-G56)/(G56))} -> -0.5 | J56: =IF(ISERROR(I56),"Предупреждение", IF(I56<0,"Ниже минимума", IF(I56=0,"Минимум", IF(I56<1,"В диапазоне", IF(I56=1,"Максимум", "Выше максимума"))))) -> Ниже минимума
A57: 54 | B57: 46035 | C57: Общество с ограниченной ответственностью Управляющая Компания "Юнион Инвест Групп" | D57: Юридическое лицо | E57: ч.12 ст.15.29 КоАП РФ | F57: 150000 | G57: 300000 | H57: 500000 | I57: {=_xlfn.IFS(F57=H57,1,F57=G57,0,F57<>G57,(F57-G57)/(G57))} -> -0.5 | J57: =IF(ISERROR(I57),"Предупреждение", IF(I57<0,"Ниже минимума", IF(I57=0,"Минимум", IF(I57<1,"В диапазоне", IF(I57=1,"Максимум", "Выше максимума"))))) -> Ниже минимума
...

Sheet чистые данные
A1: Номер случая | B1: Дата постановления | C1: Субъект | D1: Тип лица | E1: Статья КоАП | F1: Штраф факт | G1: мин | H1: макс | I1: вид штрафа | J1: Содержание статьи | K1: Описание
A2: 1 | B2: 46070 | C2: Акционерное общество «Негосударственный пенсионный фонд «Ростех» | D2: Юридическое лицо | E2: ч.9 ст.15.29 КоАП РФ | F2: 700000 | G2: 700000 | H2: 1000000 | I2: Минимум | J2: =VLOOKUP(E2,статьи!$G$2:$H$24,2,TRUE) -> 1. Неисполнение акционерным обществом, профессиональным участником рынка ценных бумаг, управляющей компанией акционерного инвестиционного фонда, паевого инвестиционного фонда или негосударственного пенсионного фонда либо специализированным депозитарием акционерного инвестиционного фонда, паевого инвестиционного фонда или негосударственного пенсионного фонда обязанности по хранению документов, которые предусмотрены законодательством об акционерных обществах, о рынке ценных бумаг, об инвестиционных фондах и принятыми в соответствии с ним нормативными правовыми актами и хранение которых является обязательным, а также нарушение установленных порядка и сроков хранения таких документов | K2: =VLOOKUP(A2,'компании+описание'!$A$1:$D$438,4,) -> По результатам рассмотрения материалов дела об административном правонарушении № ЦА-38-ЮЛ-26-258, возбуждённого за совершение административного правонарушения, ответственность за которое предусмотрена частью 9 статьи 15.29 Кодекса Российской Федерации об административных правонарушениях, АО «НПФ «Ростех» назначено административное наказание в виде штрафа в размере 700 000 рублей. Постановление вступило в законную силу 17.02.2026.
